import { assertEx } from "../lib/assertEx";
import { assert } from "chai";
import { AssertionError } from "assert";

describe("assertEx.ts", function () {
  describe("contains()", function () {
    it(`with undefined value and "test" substring`, function () {
      const error: Error = assertEx.throws(() => assertEx.contains(undefined, "test"));
      assert.strictEqual(error.message, `Expected\n  undefined\nto contain\n  "test".`);
    });

    it(`with null value and "test" substring`, function () {
      // tslint:disable-next-line:no-null-keyword
      const error: Error = assertEx.throws(() => assertEx.contains(null as any, "test"));
      assert.strictEqual(error.message, `Expected\n  null\nto contain\n  "test".`);
    });

    it(`with "" value and "test" substring`, function () {
      const error: Error = assertEx.throws(() => assertEx.contains("", "test"));
      assert.strictEqual(error.message, `Expected\n  ""\nto contain\n  "test".`);
    });

    it(`with "abc" value and undefined substring`, function () {
      const error: Error = assertEx.throws(() => assertEx.contains("abc", undefined as any));
      assert.strictEqual(error.message, `Expected\n  "abc"\nto contain\n  undefined.`);
    });

    it(`with "abc" value and null substring`, function () {
      // tslint:disable-next-line:no-null-keyword
      const error: Error = assertEx.throws(() => assertEx.contains("abc", null as any));
      assert.strictEqual(error.message, `Expected\n  "abc"\nto contain\n  null.`);
    });

    it(`with "abc" value and "" substring`, function () {
      const error: Error = assertEx.throws(() => assertEx.contains("abc", ""));
      assert.strictEqual(error.message, `Expected\n  "abc"\nto contain\n  "".`);
    });

    it(`with "abc" value and "test" substring`, function () {
      const error: Error = assertEx.throws(() => assertEx.contains("abc", "test"));
      assert.strictEqual(error.message, `Expected\n  "abc"\nto contain\n  "test".`);
    });

    it(`with "abtestc" value and "test" substring`, function () {
      assertEx.contains("abtestc", "test");
    });

    it(`with ["abtestc"] value and "test" substring`, function () {
      const error: Error = assertEx.throws(() => assertEx.contains(["abtestc"], "test"));
      assert.strictEqual(error.message,
`Expected [
  "abtestc"
] to contain
  "test".`);
    });

    it(`with ["abtestc"] value and "abtestc" substring`, function () {
      assertEx.contains(["abtestc"], "abtestc");
    });
  });

  describe("equalErrors()", function () {
    it("with different errors", function () {
      assertEx.throws(() => assertEx.equalErrors(new Error("a"), new Error("b")), (error: AssertionError) => {
        assert(error.actual);
        assert.strictEqual((error.actual as any).message, "a");
        assert(error.expected);
        assert.strictEqual((error.expected as any).message, "b");
      });
    });

    it("with equal errors", function () {
      assertEx.equalErrors(new Error("a"), new Error("a"));
    });
  });

  describe("throws(Function)", function () {
    it("with no thrown error", function () {
      const error: Error = assertEx.throws(() => assertEx.throws(() => { }));
      assertEx.equalErrors(error, new AssertionError({
        message: "Missing expected exception.",
        operator: "throws"
      }));
    });

    it("with thrown Error", function () {
      const error: Error = assertEx.throws(() => { throw new Error("abc"); });
      assertEx.equalErrors(error, new Error("abc"));
    });
  });

  describe("throws(Function,Error)", function () {
    it("with no thrown error", function () {
      const error: Error = assertEx.throws(() => assertEx.throws(() => { }, new Error("hello")));
      assertEx.equalErrors(error, new AssertionError({
        message: "Missing expected exception.",
        operator: "throws"
      }));
    });

    it("with different error message", function () {
      const error: AssertionError = assertEx.throws(() => assertEx.throws(() => { throw new Error("abc"); }, new Error("hello")));
      assert(error.actual);
      assert.strictEqual((error.actual as any).message, "abc");
      assert(error.expected);
      assert.strictEqual((error.expected as any).message, "hello");
    });

    it("with equal error", function () {
      assertEx.throws(() => { throw new Error("abc"); }, new Error("abc"));
    });
  });

  describe("throws(Function,Function)", function () {
    it("with no thrown error", function () {
      const error: Error = assertEx.throws(() => assertEx.throws(() => {}, () => {}));
      assertEx.equalErrors(error, new AssertionError({
        message: "Missing expected exception.",
        operator: "throws"
      }));
    });

    it("with assertion failure in error check function", function () {
      const error: AssertionError = assertEx.throws(() => assertEx.throws(() => { throw new Error("a"); },
        (expectedError: Error) => { assert.strictEqual(expectedError.message, "b"); }));
      assert.strictEqual(error.actual, "a");
      assert.strictEqual(error.expected, "b");
      assert.strictEqual(error.message, "expected 'a' to equal 'b'");
    });
  });

  describe("throwsAsync(Promise)", function () {
    it("with no thrown error", async function () {
      await assertEx.throwsAsync(assertEx.throwsAsync(Promise.resolve()),
        new AssertionError({
        message: "Missing expected exception.",
        operator: "throws"
      }));
    });

    it("with thrown Error", async function () {
      const rejectedPromise = Promise.reject(new Error("abc"));
      const error: Error = await assertEx.throwsAsync(rejectedPromise);
      assertEx.equalErrors(error, new Error("abc"));
    });
  });

  describe("throwsAsync(Promise,Error)", function () {
    it("with no thrown error", async function () {
      await assertEx.throwsAsync(assertEx.throwsAsync(Promise.resolve(), new Error("hello")),
        new AssertionError({
          message: "Missing expected exception.",
          operator: "throws"
        }));
    });

    it("with different error message", async function () {
      await assertEx.throwsAsync(assertEx.throwsAsync(Promise.reject(new Error("abc")), new Error("hello"))),
        new AssertionError({
          actual: new Error("abc"),
          expected: new Error("hello"),
          operator: "deepStrictEqual"
        });
    });

    it("with equal error", async function () {
      await assertEx.throwsAsync(Promise.reject(new Error("abc")), new Error("abc"));
    });
  });

  describe("throwsAsync(Promise,Function)", function () {
    it("with no thrown error", async function () {
      await assertEx.throwsAsync(assertEx.throwsAsync(Promise.resolve(), () => {}),
        new AssertionError({
          message: "Missing expected exception.",
          operator: "throws"
        }));
    });

    it("with assertion failure in error check function", async function () {
      const error: AssertionError = await assertEx.throwsAsync(assertEx.throwsAsync(Promise.reject(new Error("a")),
        (expectedError: Error) => { assert.strictEqual(expectedError.message, "b"); }));
      assert.strictEqual(error.actual, "a");
      assert.strictEqual(error.expected, "b");
      assert.strictEqual(error.message, "expected 'a' to equal 'b'");
    });
  });

  describe("throwsAsync(Function)", function () {
    it("with no thrown error", async function () {
      await assertEx.throwsAsync(assertEx.throwsAsync(async () => {}),
        new AssertionError({
        message: "Missing expected exception.",
        operator: "throws"
      }));
    });

    it("with thrown Error", async function () {
      const error: Error = await assertEx.throwsAsync(async () => { throw new Error("abc"); });
      assertEx.equalErrors(error, new Error("abc"));
    });
  });

  describe("throwsAsync(Function,Error)", function () {
    it("with no thrown error", async function () {
      await assertEx.throwsAsync(assertEx.throwsAsync(async () => {}, new Error("hello")),
        new AssertionError({
          message: "Missing expected exception.",
          operator: "throws"
        }));
    });

    it("with different error message", async function () {
      await assertEx.throwsAsync(assertEx.throwsAsync(async () => { throw new Error("abc"); }, new Error("hello"))),
        new AssertionError({
          actual: new Error("abc"),
          expected: new Error("hello"),
          operator: "deepStrictEqual"
        });
    });

    it("with equal error", async function () {
      await assertEx.throwsAsync(async () => { throw new Error("abc"); }, new Error("abc"));
    });
  });

  describe("throwsAsync(Function,Function)", function () {
    it("with no thrown error", async function () {
      await assertEx.throwsAsync(assertEx.throwsAsync(async () => {}, () => {}),
        new AssertionError({
          message: "Missing expected exception.",
          operator: "throws"
        }));
    });

    it("with assertion failure in error check function", async function () {
      const error: AssertionError = await assertEx.throwsAsync(assertEx.throwsAsync(async () => { throw new Error("a"); },
        (expectedError: Error) => { assert.strictEqual(expectedError.message, "b"); }));
      assert.strictEqual(error.actual, "a");
      assert.strictEqual(error.expected, "b");
      assert.strictEqual(error.message, "expected 'a' to equal 'b'");
    });
  });
});
